Workbook

Sheet Сводка
A1: Сухие строительные смеси — ассортимент трёх производителей (разведка 09.10.2026)
A2: Считаются товары без учёта цвета и фасовки. Источник — полный обход каталогов td-perel.ru, dauer.ru, osnovit.ru 09.10.2026 (лист «Как собрано»). Числа считаются формулами из листа «Товары».
A4: Раздел будущего сайта | B4: Perel | C4: Dauer | D4: Основит | E4: Всего | F4: У скольких производителей
A5: Цветные кладочные растворы | B5: =COUNTIFS(Товары!$A$2:$A$272,"Perel",Товары!$B$2:$B$272,$A5,Товары!$C$2:$C$272,"<>нет") | C5: =COUNTIFS(Товары!$A$2:$A$272,"Dauer",Товары!$B$2:$B$272,$A5,Товары!$C$2:$C$272,"<>нет") | D5: =COUNTIFS(Товары!$A$2:$A$272,"Основит",Товары!$B$2:$B$272,$A5,Товары!$C$2:$C$272,"<>нет") | E5: =SUM(B5:D5) | F5: =(B5>0)+(C5>0)+(D5>0)
A6: Кладочные растворы: рядовые и белые/серые | B6: =COUNTIFS(Товары!$A$2:$A$272,"Perel",Товары!$B$2:$B$272,$A6,Товары!$C$2:$C$272,"<>нет") | C6: =COUNTIFS(Товары!$A$2:$A$272,"Dauer",Товары!$B$2:$B$272,$A6,Товары!$C$2:$C$272,"<>нет") | D6: =COUNTIFS(Товары!$A$2:$A$272,"Основит",Товары!$B$2:$B$272,$A6,Товары!$C$2:$C$272,"<>нет") | E6: =SUM(B6:D6) | F6: =(B6>0)+(C6>0)+(D6>0)
A7: Тёплые (теплоизоляционные) кладочные растворы | B7: =COUNTIFS(Товары!$A$2:$A$272,"Perel",Товары!$B$2:$B$272,$A7,Товары!$C$2:$C$272,"<>нет") | C7: =COUNTIFS(Товары!$A$2:$A$272,"Dauer",Товары!$B$2:$B$272,$A7,Товары!$C$2:$C$272,"<>нет") | D7: =COUNTIFS(Товары!$A$2:$A$272,"Основит",Товары!$B$2:$B$272,$A7,Товары!$C$2:$C$272,"<>нет") | E7: =SUM(B7:D7) | F7: =(B7>0)+(C7>0)+(D7>0)
A8: Расшивка швов кирпичной кладки | B8: =COUNTIFS(Товары!$A$2:$A$272,"Perel",Товары!$B$2:$B$272,$A8,Товары!$C$2:$C$272,"<>нет") | C8: =COUNTIFS(Товары!$A$2:$A$272,"Dauer",Товары!$B$2:$B$272,$A8,Товары!$C$2:$C$272,"<>нет") | D8: =COUNTIFS(Товары!$A$2:$A$272,"Основит",Товары!$B$2:$B$272,$A8,Товары!$C$2:$C$272,"<>нет") | E8: =SUM(B8:D8) | F8: =(B8>0)+(C8>0)+(D8>0)
A9: Клей для блоков и газобетона | B9: =COUNTIFS(Товары!$A$2:$A$272,"Perel",Товары!$B$2:$B$272,$A9,Товары!$C$2:$C$272,"<>нет") | C9: =COUNTIFS(Товары!$A$2:$A$272,"Dauer",Товары!$B$2:$B$272,$A9,Товары!$C$2:$C$272,"<>нет") | D9: =COUNTIFS(Товары!$A$2:$A$272,"Основит",Товары!$B$2:$B$272,$A9,Товары!$C$2:$C$272,"<>нет") | E9: =SUM(B9:D9) | F9: =(B9>0)+(C9>0)+(D9>0)
A10: Гипсовый монтажный клей (ГКЛ, ПГП) | B10: =COUNTIFS(Товары!$A$2:$A$272,"Perel",Товары!$B$2:$B$272,$A10,Товары!$C$2:$C$272,"<>нет") | C10: =COUNTIFS(Товары!$A$2:$A$272,"Dauer",Товары!$B$2:$B$272,$A10,Товары!$C$2:$C$272,"<>нет") | D10: =COUNTIFS(Товары!$A$2:$A$272,"Основит",Товары!$B$2:$B$272,$A10,Товары!$C$2:$C$272,"<>нет") | E10: =SUM(B10:D10) | F10: =(B10>0)+(C10>0)+(D10>0)
A11: Цементно-песчаные смеси М150–М400, пескобетон | B11: =COUNTIFS(Товары!$A$2:$A$272,"Perel",Товары!$B$2:$B$272,$A11,Товары!$C$2:$C$272,"<>нет") | C11: =COUNTIFS(Товары!$A$2:$A$272,"Dauer",Товары!$B$2:$B$272,$A11,Товары!$C$2:$C$272,"<>нет") | D11: =COUNTIFS(Товары!$A$2:$A$272,"Основит",Товары!$B$2:$B$272,$A11,Товары!$C$2:$C$272,"<>нет") | E11: =SUM(B11:D11) | F11: =(B11>0)+(C11>0)+(D11>0)
A12: Штукатурки гипсовые | B12: =COUNTIFS(Товары!$A$2:$A$272,"Perel",Товары!$B$2:$B$272,$A12,Товары!$C$2:$C$272,"<>нет") | C12: =COUNTIFS(Товары!$A$2:$A$272,"Dauer",Товары!$B$2:$B$272,$A12,Товары!$C$2:$C$272,"<>нет") | D12: =COUNTIFS(Товары!$A$2:$A$272,"Основит",Товары!$B$2:$B$272,$A12,Товары!$C$2:$C$272,"<>нет") | E12: =SUM(B12:D12) | F12: =(B12>0)+(C12>0)+(D12>0)
A13: Штукатурки цементные и цементно-известковые (вкл. обрызг) | B13: =COUNTIFS(Товары!$A$2:$A$272,"Perel",Товары!$B$2:$B$272,$A13,Товары!$C$2:$C$272,"<>нет") | C13: =COUNTIFS(Товары!$A$2:$A$272,"Dauer",Товары!$B$2:$B$272,$A13,Товары!$C$2:$C$272,"<>нет") | D13: =COUNTIFS(Товары!$A$2:$A$272,"Основит",Товары!$B$2:$B$272,$A13,Товары!$C$2:$C$272,"<>нет") | E13: =SUM(B13:D13) | F13: =(B13>0)+(C13>0)+(D13>0)
A14: Шпаклёвки гипсовые | B14: =COUNTIFS(Товары!$A$2:$A$272,"Perel",Товары!$B$2:$B$272,$A14,Товары!$C$2:$C$272,"<>нет") | C14: =COUNTIFS(Товары!$A$2:$A$272,"Dauer",Товары!$B$2:$B$272,$A14,Товары!$C$2:$C$272,"<>нет") | D14: =COUNTIFS(Товары!$A$2:$A$272,"Основит",Товары!$B$2:$B$272,$A14,Товары!$C$2:$C$272,"<>нет") | E14: =SUM(B14:D14) | F14: =(B14>0)+(C14>0)+(D14>0)
A15: Шпаклёвки цементные | B15: =COUNTIFS(Товары!$A$2:$A$272,"Perel",Товары!$B$2:$B$272,$A15,Товары!$C$2:$C$272,"<>нет") | C15: =COUNTIFS(Товары!$A$2:$A$272,"Dauer",Товары!$B$2:$B$272,$A15,Товары!$C$2:$C$272,"<>нет") | D15: =COUNTIFS(Товары!$A$2:$A$272,"Основит",Товары!$B$2:$B$272,$A15,Товары!$C$2:$C$272,"<>нет") | E15: =SUM(B15:D15) | F15: =(B15>0)+(C15>0)+(D15>0)
A16: Шпаклёвки полимерные (сухие) | B16: =COUNTIFS(Товары!$A$2:$A$272,"Perel",Товары!$B$2:$B$272,$A16,Товары!$C$2:$C$272,"<>нет") | C16: =COUNTIFS(Товары!$A$2:$A$272,"Dauer",Товары!$B$2:$B$272,$A16,Товары!$C$2:$C$272,"<>нет") | D16: =COUNTIFS(Товары!$A$2:$A$272,"Основит",Товары!$B$2:$B$272,$A16,Товары!$C$2:$C$272,"<>нет") | E16: =SUM(B16:D16) | F16: =(B16>0)+(C16>0)+(D16>0)
... A27: Краска сухая (цементно-известковая) | B27: =COUNTIFS(Товары!$A$2:$A$272,"Perel",Товары!$B$2:$B$272,$A27,Товары!$C$2:$C$272,"<>нет") | C27: =COUNTIFS(Товары!$A$2:$A$272,"Dauer",Товары!$B$2:$B$272,$A27,Товары!$C$2:$C$272,"<>нет") | D27: =COUNTIFS(Товары!$A$2:$A$272,"Основит",Товары!$B$2:$B$272,$A27,Товары!$C$2:$C$272,"<>нет") | E27: =SUM(B27:D27) | F27: =(B27>0)+(C27>0)+(D27>0)
A28: Итого сухих смесей | B28: =SUM(B5:B27) | C28: =SUM(C5:C27) | D28: =SUM(D5:D27) | E28: =SUM(E5:E27)
A30: Сопутствующие не сухие товары (грунты, краски, пасты, добавки, бытовая химия) | B30: =COUNTIFS(Товары!$A$2:$A$272,"Perel",Товары!$C$2:$C$272,"нет") | C30: =COUNTIFS(Товары!$A$2:$A$272,"Dauer",Товары!$C$2:$C$272,"нет") | D30: =COUNTIFS(Товары!$A$2:$A$272,"Основит",Товары!$C$2:$C$272,"нет") | E30: =SUM(B30:D30)
A31: Разделов, где позиции есть у всех трёх | E31: =COUNTIF(F5:F27,3)
A32: Разделов, где позиции есть только у одного | E32: =COUNTIF(F5:F27,1)
A34: Цветные кладочные растворы — тема соседнего сайта «Цветные кладочные смеси»: здесь коротко и ссылкой.

Sheet Товары
A1: Производитель | B1: Раздел будущего сайта | C1: Сухая смесь | D1: Товар (без цвета и фасовки) | E1: Название на сайте производителя | F1: Карточек у производителя (цвета, фасовки) | G1: Назначение — дословно | H1: Фасовка — дословно | I1: Расход — дословно | J1: Толщина слоя или шва — дословно | K1: Норматив — дословно | L1: Зимняя версия | M1: Цвета — дословно | N1: Ссылка на карточку | O1: Примечание разбора
A2: Dauer | B2: Цветные кладочные растворы | C2: да | D2: Dauer BRICK.COLOR 250 | E2: Dauer BRICK.COLOR 250 цветная кладочная смесь армированная | F2: 1 | G2: Для монтажа и одновременной отделки швов кладочных элементов с водопоглощением от 6 до 12% | H2: 3,5 – 4,5 литра воды на мешок 25 кг или 7 – 9 литров на мешок 50 кг | J2: 5-15 мм | K2: ГОСТ Р 58272 | L2: есть | M2: 25 цветов | N2: https://dauer.ru/catalog/montazhnye-i-kladochnye/dauer-brick-color-250/ | O2: Строки «Фасовка» на карточке нет: мешки 25 и 50 кг упомянуты только в приготовлении раствора; «Смесь поставляется в бумажных мешках». Есть зимняя версия (характеристики «(зимняя версия)», нанесение -10…+30°С; PDF «+ЗИМА»). Внутренние/наружные работы не указаны. Расход раствора не указан. Список 25 цветов на карточке текстом не приведён. Минимальное оседание раствора в пустотах кирпича (особенности
A3: Dauer | B3: Цветные кладочные растворы | C3: да | D3: Dauer BRICK.COLOR 251 | E3: Dauer BRICK.COLOR 251 цветная кладочная смесь армированная | F3: 1 | G3: Для монтажа и одновременной отделки швов кладочных элементов с водопоглощением от 5 до 18% (полнотелый и пустотелый облицовочный керамический кирпич, кирпич ручной формовки, рядовой керамический и плотный силикатный кирпич, кирпичи или блоки из бетона и натурального камня). | H3: 3,5 – 4,5 литра воды на мешок 25 кг или 7 – 9 литров на мешок 50 кг | J3: 5-15 мм | K3: ГОСТ Р 58272 | L3: есть | M3: 25 цветов | N3: https://dauer.ru/catalog/montazhnye-i-kladochnye/dauer-brick-color-251/ | O3: Строки «Фасовка» нет: мешки 25 и 50 кг упомянуты только в приготовлении раствора. Есть зимняя версия (характеристики «(зимняя версия)», нанесение -10…+30°С; PDF «+ЗИМА»). Внутренние/наружные работы не указаны. Расход раствора не указан. Список 25 цветов на карточке текстом не приведён. Добавка против высолов (особенности).
A4: Dauer | B4: Цветные кладочные растворы | C4: да | D4: Dauer BRICK.COLOR 252 | E4: Dauer BRICK.COLOR 252 цветная кладочная смесь армированная | F4: 1 | G4: Для монтажа и одновременной отделки швов кладочных элементов с водопоглощением от 1 до 5% (полнотелый и пустотелый облицовочный клинкерный кирпич, блоки из бетона и натурального камня). | H4: Смесь поставляется в бумажных мешках. | J4: 5-15 мм | K4: ГОСТ Р 58272 | L4: есть | M4: 25 цветов | N4: https://dauer.ru/catalog/montazhnye-i-kladochnye/dauer-brick-color-252/ | O4: Масса мешка не указана вовсе (только «бумажные мешки»), раздела «Выполнение работ» на карточке нет. Для клинкера: марка 15 МПа, морозостойкость 150 циклов. Есть зимняя версия (характеристики «(зимняя версия)», нанесение -10…+30°С; PDF «+ЗИМА»). Внутренние/наружные работы не указаны. Расход раствора не указан. Список 25 цветов на карточке текстом не приведён.
A5: Perel | B5: Цветные кладочные растворы | C5: да | D5: Perel NL | E5: Белая кладочная смесь Perel NL 0105, 25 кг | F5: 28 | G5: Цветная смесь Perel NL 0105 для кладки облицовочного кирпича с низким водопоглощением от 0 до 5% (клинкерный кирпич и т.п.). | H5: фасовка 50 кг | K5: Нанесение смеси производить в соответствии со СП 70.13330.2012 | L5: есть | N5: https://td-perel.ru/catalog/perel-nl/belaya-kladochnaya-smes-perel-nl-25-kg/ | O5: Цветной кладочный для клинкера (пересечение с сайтом «Цветные кладочные смеси»). Артикул: в названии и описании 0105, в характеристиках 0101 — какой верный, не ясно. Общие замечания по NL — в batch_notes.
A6: Perel | B6: Цветные кладочные растворы | C6: да | D6: Perel SL | E6: Белая кладочная смесь Perel SL 0005, 25 кг | F6: 28 | G6: Цветная смесь Perel SL 0005 для кладки облицовочного кирпича с средним водопоглощением от 5 до 12 % (керамический кирпич и т.п.). | H6: фасовка 50 кг | K6: СП 70.13330.2012 | L6: есть | M6: цвет красный | N6: https://td-perel.ru/catalog/perel-sl/belaya-kladochnaya-smes-perel-sl-25-kg/ | O6: В заголовке единственной из пачки стоит артикул («SL 0005, 25 кг»). Белый внутри цветной линейки SL — тип masonry_colored. Расхода нет; толщина шва числом не указана. «Зима» упомянута в описании, отдельной карточки нет.
A7: Perel | B7: Цветные кладочные растворы | C7: да | D7: Perel VL | E7: Белая кладочная смесь Perel VL 0205, 25 кг | F7: 28 | G7: Цветная смесь Perel VL 0205 для кладки облицовочного кирпича с высоким водопоглощением от 5 до 17% (кирпич ручной формовки и т.п.). | H7: фасовка 25 кг | K7: СП 70.13330.2012 | L7: есть | M7: цвет бежевый | N7: https://td-perel.ru/catalog/perel-vl/belaya-kladochnaya-smes-perel-vl-25-kg/ | O7: белый цвет внутри цветной линейки VL (оставлен masonry_colored); артикул 0205 вынесен в заголовок; основа вяжущего и расход на кладку не указаны; модификация «зима» упоминается только в описании
A8: Основит | B8: Цветные кладочные растворы | C8: да | D8: Основит Брикформ MC11 | E8: Раствор кладочный зимний для облицовочного кирпича Основит Брикформ MC11 F 25 кг | F8: 3 | G8: Кладочный раствор ОСНОВИТ БРИКФОРМ МС11 F зимний предназначен для кладки стен из облицовочного кирпича с водопоглощением до 12% с возможностью расшивки швов в момент укладки при температуре окружающей среды и основания от -10 до + 10°С. | H8: Мешок 25кг | I8: Расход смеси, кг на 1м² кладки (ложковая кладка) 50 кг | J8: Рекомендуемая толщина шва кладки 5-15 мм | K8: G M100, ГОСТ Р 58272-2018 | L8: есть | M8: 17 цветов | N8: https://osnovit.ru/catalog/kladochnye-rastvory/kladochnyy-rastvor-osnovit-brikform-ms11-f-zimniy-belyy-010/ | O8: URL карточки «…zimniy-belyy-010», но страница описывает весь MC11 F (17 цветов); есть оговорка о фасовке в мешок «БРИКФОРМ МС11 БЕЛЫЙ 010» со стикером «зимний». Расхождение температур: в назначении «от -10 до + 10°С», в характеристиках «-10…+5 ºС». Строка «Прочность сцепления с основанием» в характеристиках повторена дважды. Документация (описание, техкарта) названа, но ссылок PDF во входе нет. Ле
A9: Основит | B9: Цветные кладочные растворы | C9: да | D9: Основит Брикформ MC11/1 | E9: Раствор кладочный зимний белый для облицовочного кирпича Основит Брикформ MC11/1 F 25 кг | F9: 3 | G9: предназначен для кладки стен и перегородок из облицовочного кирпича водопоглощением более 12% с возможностью расшивки швов в момент укладки при температуре окружающей среды и основания от -10 до + 10°С. | H9: Мешок 25кг | I9: 50 кг | J9: 5-15 мм | K9: G M100, ГОСТ Р 58272-2018 | L9: есть | M9: 34 цвета | N9: https://osnovit.ru/catalog/kladochnye-rastvory/kladochnyy-rastvor-osnovit-brikform-ms11-1-f/ | O9: Зимняя модификация линии Брикформ MC11/1 (раздел «Цветные кладочные растворы»), но в зиме только белый цвет — тип masonry_colored выбран по линейке, можно считать и masonry_ordinary. Пересекается с сайтом «Цветные кладочные смеси». Расход 50 кг на 1 м² ложковой кладки. Описание «от -10 до + 10°С», характеристики «-10…+5 ºС». Строка «Прочность сцепления с основанием» на странице повторена дважды; о
A10: Dauer | B10: Кладочные растворы: рядовые и белые/серые | C10: да | D10: Dauer BRICK.COLOR 253 | E10: Dauer BRICK.COLOR 253 кладочная смесь для рядового кирпича | F10: 1 | G10: Предназначена для монтажа забутовочных кладочных элементов (полнотелый и пустотелый керамический кирпич, натуральный камень, рядовой керамический и плотный силикатный кирпич, кирпичи из бетона). | H10: 3,25 – 3,75 литра воды на мешок 25 кг или 6,5 – 7,5 литров на мешок 50 кг | J10: 5-20 мм | K10: ГОСТ Р 58272 | L10: есть | N10: https://dauer.ru/catalog/montazhnye-i-kladochnye/dauer-brick-color-253/ | O10: Сомнение в типе: линейка BRICK.COLOR, но H1 «кладочная смесь для рядового кирпича», назначение — забутовочная кладка, цвета не указаны → masonry_ordinary. Строки «Фасовка» нет: мешки 25 и 50 кг упомянуты только в приготовлении раствора. Расход раствора не указан. Есть зимняя версия (PDF «+ЗИМА»). Внутр./наруж. не указано, но шов описан как свето-, водо- и морозостойкий.
A11: Основит | B11: Кладочные растворы: рядовые и белые/серые | C11: да | D11: Основит Рокформ MC110 | E11: Раствор кладочный для рядового кирпича Основит Рокформ MC110 25 кг | F11: 3 | G11: Кладочный раствор ОСНОВИТ РОКФОРМ МС110 предназначен для забутовки и кладки стен из облицовочного и рядового кирпича. | H11: 25 кг | I11: 400-440 кг | J11: 5-15 мм | K11: G M150, ГОСТ Р 58272-2018 | L11: есть | M11: серый | N11: https://osnovit.ru/catalog/kladochnye-rastvory-osnovit/rokform-ms110-N/ | O11: URL с суффиксом «-N», в title страницы «(25 кг) Н» — возможно, старая/дублирующая версия карточки Рокформ MC110 из другой пачки; сверить при склейке. ГОСТ/марка смеси на странице не указаны. Тип: серый кладочный для рядового и облицовочного кирпича (masonry_ordinary); можно спорить с masonry_universal_cps. Зимняя версия «Рокформ MC110 F» упоминается только в сопутствующих товарах других карточек.
A12: Dauer | B12: Тёплые (теплоизоляционные) кладочные растворы | C12: да | D12: Dauer TEFIX LM | E12: Dauer TEFIX LM Кладочный раствор для теплой керамики | F12: 1 | G12: Предназначен для возведения несущих и ограждающих конструкций из «теплой» керамики, газобетона и легкого пустотелого кирпича, а также блоков из бетона на пористых заполнителях (керамзитобетон). | H12: 20 кг. | I12: Расход раствора при слое шва 12 мм | J12: 5-20 мм | K12: ГОСТ Р 58272 | L12: есть | N12: https://dauer.ru/catalog/montazhnye-i-kladochnye/tefix-lm-kladochnyy-rastvor/ | O12: Полное наименование «Dauer Quader Tefix LM» (TEFIX — подлинейка QUADER). Содержит перлит и армирующие волокна. Расход при шве 12 мм таблицей (формат / толщина стены / на 1 м2 кладки / на 1 блок): 4,5 NF 8 см ~6 кг ~0,6 кг; 6,7 NF 12 см ~8 кг ~0,9 кг; 10,7 NF 38 см ~27 кг ~1,6 кг; 12,3 NF 44 см ~32 кг ~1,8 кг; 14,3 NF 51 см ~35 кг ~2,0 кг. Есть зимняя версия.
A13: Dauer | B13: Тёплые (теплоизоляционные) кладочные растворы | C13: да | D13: Dauer TEFIX SM | E13: Dauer TEFIX SM Кладочный раствор теплоизоляционный | F13: 1 | G13: Предназначен для возведения несущих и ограждающих стен из поризованных керамических блоков, легких блоков из ячеистого бетона (в т.ч. пено- и газобетон), а также блоков из бетона на пористых заполнителях (керамзитобетон). | H13: 25 кг. | I13: РАСХОД РАСТВОРА ПРИ СЛОЕ ШВА 12 мм | J13: 5 - 20 мм | K13: ГОСТ Р 58272 | L13: есть | N13: https://dauer.ru/catalog/montazhnye-i-kladochnye/quader-tefix-sm/ | O13: Полное наименование «Dauer Quader Tefix SM». Расхождение: фасовка 25 кг, а вода дана «на 30 кг смеси» (7,8 – 9,6л). Подвижность записана «150 + 10 мм» (у соседей «±»). Расход при шве 12 мм таблицей (на 1 м2 кладки / на 1 блок): 4,5 NF ~7 кг ~0,7 кг; 6,7 NF ~10 кг ~1,0 кг; 10,7 NF ~32 кг ~1,8 кг; 12,3 NF ~38 кг ~2,1 кг; 14,3 NF ~42 кг ~2,4 кг. Есть зимняя версия (срок годности 6 месяцев).
A14: Dauer | B14: Тёплые (теплоизоляционные) кладочные растворы | C14: да | D14: Dauer TEFIX SW | E14: Dauer TEFIX SW Кладочный раствор для теплой керамики | F14: 1 | G14: Предназначен для возведения несущих и ограждающих конструкций из «теплой» керамики, газобетона и легкого пустотелого кирпича, а также блоков из бетона на пористых заполнителях (керамзитобетон). | H14: 17,5 кг. | J14: 5-20 мм | K14: ГОСТ Р 58272 | L14: есть | N14: https://dauer.ru/catalog/montazhnye-i-kladochnye/tefix-sw/ | O14: Полное наименование «Dauer Quader Tefix SW». Фасовка 17,5 кг; «Выход до 34 л.*» — «*Максимальный показатель полученный в лабораторных условиях»; плотность 800 кг/м3 (самая лёгкая из TEFIX). Таблицы расхода нет. Есть зимняя версия.
A15: Perel | B15: Тёплые (теплоизоляционные) кладочные растворы | C15: да | D15: Perel TKS 2020 | E15: Теплая кладочная смесь Perel TKS 2020, 25 кг | F15: 1 | G15: Теплая смесь Perel TKS 2020 (усиленная) применяется в качестве раствора для кладки теплых блоков, таких как крупноформатные поризованные керамические блоки, поризованные керамические камни, арболит и т.п.. | H15: Бумажные крафт-мешки: 25 кг | L15: — | N15: https://td-perel.ru/catalog/teplaya-kladochnaya-smes/teplaya-kladochnaya-smes-2020/ | O15: Короткое описание упоминает арболит, полное — нет. «Выход раствора 1,0 – 1,1 л/кг» — это выход, не расход, поэтому consumption пуст. Нанесение по СП 70.13330.2012 (свод правил на кладку, не стандарт продукта — в normative не ставил). Зимней модификации на карточке нет. В конце ядра служебные строки «SEOTEG01 / arbolit».
A16: Perel | B16: Тёплые (теплоизоляционные) кладочные растворы | C16: да | D16: Perel TKS 6020 | E16: Теплая кладочная смесь Perel TKS 6020, 20 кг | F16: 1 | G16: Теплая смесь Perel TKS 6020 (экономичная) применяется в качестве раствора для каменной и (или) кирпичной кладки материалов с повышенными теплоизоляционными свойствами, таких как крупноформатные поризованные керамические блоки, поризованные керамические камни. | H16: Бумажные крафт-мешки: 20 кг | L16: — | N16: https://td-perel.ru/catalog/teplaya-kladochnaya-smes/teplaya-kladochnaya-smes-20208216/ | O16: Раздел «Описание» пуст, назначение — в коротком описании. Выход 1,3 - 1,4 л/кг (не расход). Нанесение по СП 70.13330.2012. Зимней модификации на карточке нет.
A17: Perel | B17: Тёплые (теплоизоляционные) кладочные растворы | C17: да | D17: Perel TKS 8020 | E17: Теплая кладочная смесь Perel TKS 8020, 17.5 кг | F17: 1 | G17: Применяется для исключения мостиков холода при кладке теплых блоков (керамические крупноформатные блоки и т.п.) | H17: Бумажные крафт-мешки: 17,5 кг | I17: Расход сухой смеси на 1 блок (кг) 51 - (510×250×219 мм) 1,4 - 1,5 44 - (440×250×219 мм) 1,2 - 1,3 38 - (380×250×219 мм) 1 - 1,1 30 - (250×300×219 мм) 0.8 - 0,9 25 - (250×380×219 мм) 1 - 1,1 12 - (120×500×219 мм) 0,6 - 0,7 | L17: есть | N17: https://td-perel.ru/catalog/teplaya-kladochnaya-smes/perel-tks-8020/ | O17: Есть зимняя модификация: «8520 – «зима»», 17.5 кг, «от -5 °С до +10 °С» (лето 8020 — от +5 °С до +30 °С). Теплопроводность в преимуществах «< 0,17 Вт/м*К», в характеристиках «0,17 Вт/м∙°С». Выход «26 - 28 л» без «/кг» (видимо на мешок). В названии «17.5 кг» (точка), в тексте «17,5 кг». В таблице расхода опечатка «0.8 - 0,9». Расход дан на 1 блок по форматам (multi-line цитата таблицы).
A18: Основит | B18: Тёплые (теплоизоляционные) кладочные растворы | C18: да | D18: Основит Путформ MC114 | E18: Раствор кладочный теплоизоляционный зимний Основит Путформ MC114 F 20 кг | F18: 4 | G18: Теплоизоляционный кладочный раствор ОСНОВИТ ПУТФОРМ МС114 F зимний предназначен для кладки стен из лёгких пустотелых керамических блоков, блоков из бетона на пористых заполнителях при температуре окружающей среды и основания от -10 до + 10°С. | H18: Мешок 20кг | I18: Размер блока Расход смеси (готовый р-р), л Расход смеси (сухая смесь), кг 510x250x219 2,3 2,0 440x250x219 2,2 1,9 380x250x219 1,95 1,7 | J18: Рекомендуемая толщина шва кладки 5-15 мм | K18: L M50, ГОСТ Р 58272-2018 | L18: есть | M18: серый | N18: https://osnovit.ru/catalog/kladochnye-rastvory/putform-mc114-f-zimniy-teploizolyatsionnyy-kladochnyy-rastvor/ | O18: Зимняя модификация MC114 (летняя — карточка MC114 в этой пачке). Оговорка: возможна фасовка в мешок «ПУТФОРМ МС114» со стикером «зимний». Значения температур записаны небрежно («-50°С…+65°», «- 10°С…+10° ºС»). Срок хранения 6 месяцев (у летней 12/24).
A19: Основит | B19: Тёплые (теплоизоляционные) кладочные растворы | C19: да | D19: Основит Путформ MC114 L | E19: Раствор кладочный теплоизоляционный высокоэффективный Основит Путформ MC114 L 20 кг | F19: 1 | G19: Высокоэффективный теплоизоляционный кладочный раствор ОСНОВИТ ПУТФОРМ MC114 L предназначен для кладки стен из материалов с повышенными теплоизоляционными свойствами, а именно из лёгких пустотелых керамических блоков и блоков из бетона на пористых заполнителях. | H19: Вес упаковки 20 кг | I19: Размер блока Расход смеси (готовый р-р), л Расход смеси (сухая смесь), кг 510x250x219 2,3 1,6 440x250x219 2,2 1,5 380x250x219 1,95 1,3 | J19: Рекомендуемая толщина шва кладки 5-15 мм | K19: L M50, ГОСТ Р 58272-2018 | L19: — | M19: серый | N19: https://osnovit.ru/catalog/kladochnye-rastvory/osnovit-putform-mc114-l-vysokoeffektivnyy-teploizolyatsionnyy-/ | O19: Отдельная модель «L» (высокоэффективная: ниже теплопроводность 0,18-0.20, плотность 800-900, выход 28-30 л) — вынесена в свой series_key, хотя по линейке это модификация MC114; при склейке решить, держать ли отдельной позицией. В значении теплопроводности смешаны запятая и точка («0,18-0.20»). Зимней версии MC114 L в тексте нет.
A20: Основит | B20: Расшивка швов кирпичной кладки | C20: да | D20: Основит Бриксэйв XC30 | E20: Раствор цветной для расшивки швов Основит Бриксэйв XC30 20 кг | F20: 1 | G20: Раствор для расшивки швов ОСНОВИТ БРИКСЭЙВ ХС30 предназначен для отделки швов: | H20: 20 кг | I20: 5,0 | J20: 5-30 мм | L20: — | M20: 22 цвета | N20: https://osnovit.ru/catalog/rasshivki/brikseyv-xc30/ | O20: consumption_quote «5,0» — кг на 1 м² кладки (кирпич 250x120x65) при глубине и ширине шва 10 мм (подпись разбита на строки). В преимуществах «22 цветовых решений», в характеристиках «22 цвета». Пометка «Колеровка» у заголовка. Пересекается с сайтом «Цветные кладочные смеси» (цветная расшивка). Документы «Описание», «Техническая карта» — без ссылок во входе.
A21: Dauer | B21: Клей для блоков и газобетона | C21: да | D21: Dauer QUADER D600 | E21: Dauer QUADER D600 клей для блоков усиленный | F21: 1 | G21: Для возведения стен и перегородок из блоков на основе газо- и пенобетона, силикатного пенобетона, полистиролбетона и других ячеистых блоков. | H21: 25 кг, 40 кг | I21: Расход раствора при слое шва 2 мм | J21: 2-5 мм | K21: ГОСТ Р 58272 | L21: есть | N21: https://dauer.ru/catalog/montazhnye-i-kladochnye/block-d600-kley-montazhnyy/ | O21: Полное наименование «Dauer Quader Блок (Block) D600». Расход — таблицей при шве 2 мм, «Количество на 1 м 3» кладки по формату блока: 15–19 кг (первые 4 пары characteristics — формат блока → кг на 1 м3). Зимняя версия — до -10 °С / -15 °С «в зависимости от версии продукта». Документ назван «Клей монтажный тонкошовный (лето и зима)».
A22: Perel | B22: Клей для блоков и газобетона | C22: да | D22: Perel Blokus | E22: Perel Blokus 25 кг, серый | F22: 4 | G22: Для кладки блоков и плит из ячеистого бетона, пенобетона, газосиликата и газобетона и т.п.. Исключает появление «мостиков холода» в швах кладки блоков благодаря тонкослойному кладочному шву 2-5 мм. | H22: Бумажные крафт-мешки - 25 кг. | I22: 8-9 кг/м 2 стандартного блока 600*200*300 при слое кладки 5 мм. | J22: благодаря тонкослойному кладочному шву 2-5 мм | L22: — | N22: https://td-perel.ru/catalog/montazhnyy-kley/perel_blokus_25_kg_seryy/ | O22: Тот же продукт, что Blokus 40 кг серый (0340) и белые Blokus 0332/0334 — характеристики одинаковые. Морозостойкость на карточке F50 (на подборке белого клея заявлено F100). ГОСТ на карточке нет; «для внутренних и наружных работ» есть только на подборке kley-gaz. Пара «Коэффициент паропроницаемости» на странице есть, в characteristics не вошла.
A23: Основит | B23: Клей для блоков и газобетона | C23: да | D23: Основит PRO Клей для блоков | E23: Клей для блоков Основит PRO | F23: 1 | G23: Клей для блоков ОСНОВИТ PRO используется в тонкослойной кладке стен и перегородок. Предназначен для пазовых и беспазовых блоков и плит на основе ячеистого бетона (пено- и газобетон), газосиликата и силиката. | H23: 20 кг | I23: 1,3 кг/м² | J23: Для тонкого шва от 2 до 5 мм | L23: — | N23: https://osnovit.ru/catalog/osnovit-pro/kley-dlya-blokov-osnovit-pro/ | O23: Сухость — из характеристики «Расход воды на 1 кг сухой смеси» (фразы «смесь сухая» нет). Основа (цемент) не названа. Есть таблица расхода по размерам блоков (напр. 625*250*150: 0,75 кг на блок, 8 кг на м² стены, 32 кг на м³). ГОСТ не указан. Нет pdf во входе.
A24: Основит | B24: Клей для блоков и газобетона | C24: да | D24: Основит Селформ MC112 | E24: Клей монтажный зимний Основит Селформ MC112 F 20 кг | F24: 2 | G24: ОСНОВИТ СЕЛФОРМ MC112 F зимний клей монтажный предназначен для кладки стен и перегородок из блоков и плит на основе ячеистого бетона (пено- и газобетон), газосиликата и силиката при температуре окружающей среды и основания от -10 до + 10°С . | H24: Вес упаковки 20 кг | I24: Расход смеси на 1 м 3 блоков (блоки из ячеистых бетонов 20*30*60 см, шов 3 мм) 26 кг | J24: Рекомендуемая толщина слоя 1-5 мм | K24: Т M100, ГОСТ Р 58272-2018 | L24: есть | M24: серый | N24: https://osnovit.ru/catalog/montazhnye-klei/selform-mc-112-f/ | O24: Зимняя модификация MC112. Оговорка: возможна фасовка в мешок «СЕЛФОРМ МС112» со стикером «зимний». Расход дан «на 1м² блоков … 8 кг», у летней — «на 1 м 3 блоков … 26 кг» (разная база, не сравнивать напрямую). Строка «Температура эксплуатации» повторена дважды в разной записи. Срок хранения 6 месяцев.
A25: Основит | B25: Клей для блоков и газобетона | C25: да | D25: Основит Техно MC112 | E25: Клей монтажный зимний Основит Техно MC112 F 40 кг | F25: 2 | G25: Клей монтажный ОСНОВИТ ТЕХНО MC112 F предназначен для кладки стен и перегородок из блоков и плит на основе ячеистого бетона (пено- и газобетон), газосиликата и силиката при температуре окружающей среды и основания от -10 до + 10°С. | H25: 40 кг | I25: 26 кг | J25: 2-5 мм | K25: Т M100, ГОСТ Р 58272-2018 | L25: есть | N25: https://osnovit.ru/catalog/montazhnye-klei/kley-montazhnyy-osnovit-tekhno-mc112-f-zimniy/ | O25: Зимняя модификация Техно MC112. Марка/ГОСТ на карточке не указаны (у летнего — «Т M100, ГОСТ Р 58272-2018»), сухость — по «Расход воды на 1 кг сухой смеси». Расход 26 кг на 1 м3 и 8 кг на 1 м2 (блоки 20*30*60 см, шов 3 мм) — названия разорваны переносом, взяты фрагменты. Срок хранения 12 мес. (бумажный) / 24 мес. (пластиковый мешок). Бейджа «Зима» на странице нет. На карточке Брикформ MC11/1 F сос
A26: Perel | B26: Гипсовый монтажный клей (ГКЛ, ПГП) | C26: да | D26: Perel Gipsel | E26: Perel Gipsel, 30 кг, серый, гипсовый клей | F26: 2 | G26: Сухая монтажная смесь на основе гипсового вяжущего, минеральных и полимерных добавок для монтажа перегородок из гипсовых пазогребневых плит, крепления гипсовых элементов, для бескаркасного монтажа гипсокартонных и гипсоволокнистых листов (ГКЛ, ГВЛ), листов теплоизоляции к вертикальным внутри помещений с нормальной влажностью | H26: Бумажные крафт-мешки по 30 кг. | J26: Толщина вертикальных и горизонтальных швов должна быть не более 2 мм. | L26: — | N26: https://td-perel.ru/catalog/montazhnyy-kley/gipsovyy-kley-perel-gipsel/ | O26: Описание совпадает с Gipsel белый (0331); в характеристиках только артикул и цвет (у белого ещё температура, адгезия 0,3 МПа, открытое время 5 мин). Расход не указан.
A27: Основит | B27: Гипсовый монтажный клей (ГКЛ, ПГП) | C27: да | D27: Основит PRO клей гипсовый монтажный | E27: Клей гипсовый монтажный Основит PRO 20 кг | F27: 1 | G27: Клей монтажный гипсовый ОСНОВИТ PRO Предназначен для монтажа перегородок из пазогребневых плит, ремонта пазогребневых плит, крепления гипсовых элементов декора и отделки, для бескаркасного монтажа гипсокартонных и гипсоволокнистых листов (ГКЛ и ГВЛ), приклеивания теплоизоляционных материалов. | H27: Вес упаковки 20 кг | I27: Расход сухой смеси при монтаже ПГП на 1 м2 1,5-2 кг | J27: Рекомендуемая толщина слоя при монтаже ПГП 2-3 мм | K27: Т M100, ГОСТ Р 58272-2018 | L27: — | M27: серый | N27: https://osnovit.ru/catalog/osnovit-pro/kley-montazhnyy-gipsovyy-osnovit-pro/ | O27: Странность: для гипсового клея указана классификация кладочной смеси «Т M100, ГОСТ Р 58272-2018». Без кода модели — ключ по линейке PRO. Цвет «серый». Расход воды без единиц («0,43-0,45»). Карточка в разделах «Монтажные клеи» и «Основит PRO».
A28: Dauer | B28: Цементно-песчаные смеси М150–М400, пескобетон | C28: да | D28: Dauer М-150 Универсальная | E28: Dauer® Сухая смесь М-150 Универсальная | F28: 1 | G28: Сухая смесь универсальная предназначена для возведения стен и перегородок из кирпича и мелкоштучных элементов, для работ по заделке полостей, выбоин и трещин, производства различных монтажных и штукатурных работ, а также для укладки тротуарной плитки. | H28: 30 кг, 40 кг, 50 кг | I28: 19 кг/м² | J28: Толщина горизонтальных швов кладки – 10 -15 мм, вертикальных – 8 -10 мм. | K28: ГОСТ 28013-98 | L28: есть | N28: https://dauer.ru/catalog/tsementno-peschanye-smesi/sukhaya_smes_m_150_universalnaya/ | O28: Универсальная ЦПС М150: кладка, монтаж, штукатурка, тротуарная плитка. base_quote — название раздела каталога, своей фразы об основе на странице нет. Зимние модификации -10/-15°С (на сайте значение «от * °С до +30 °С»). Расхождение: в «Тип основания» прочность не менее 10 МПа, в подготовке основания — не менее 15 МПа. Расход 19 кг/м² указан на слой 10 мм.
A29: Dauer | B29: Цементно-песчаные смеси М150–М400, пескобетон | C29: да | D29: Dauer М-150 Штукатурная | E29: Dauer® Сухая смесь М-150 Штукатурная | F29: 1 | G29: Сухая смесь штукатурная предназначена для оштукатуривания стен из бетона, кирпича, камня. | H29: на 1 мешок 50 кг | I29: 19 кг/м² | J29: 10 – 30 мм | K29: ГОСТ 28013-98 | L29: есть | N29: https://dauer.ru/catalog/tsementno-peschanye-smesi/sukhaya_smes_m_150_shtukaturnaya/ | O29: Сомнение в типе: по составу это ЦПС М150 (masonry_universal_cps, раздел «Цементно-песчаные смеси»), по назначению — только штукатурка (plaster_cement). В характеристиках фасовки нет; «на 1 мешок 50 кг» взято из раздела «Выполнение работ». Расхождение по слою: в характеристиках 10–30 мм, в разделе работ «слоем 20 - 50 мм». Расход 19 кг/м² указан на слой 10 мм. Зимняя версия есть (температура «от *
A30: Dauer | B30: Цементно-песчаные смеси М150–М400, пескобетон | C30: да | D30: Dauer М-200 Монтажно-кладочная | E30: Dauer® Сухая смесь М-200 Монтажно-кладочная | F30: 1 | G30: Сухая смесь монтажно-кладочная предназначена для выполнения общестроительных работ: устройство "мокрых" стяжек; заделка швов, трещин, выбоин, углублений; возведение стен и конструкций из полнотелого рядового кирпича, полнотелых бетонных блоков и природного камня. | H30: на 1 мешок 50 кг | I30: 20 кг/м² | J30: Толщина горизонтальных швов кладки – 10-15 мм, вертикальных – 8-10 мм. | K30: ГОСТ 28013-98 | L30: есть | N30: https://dauer.ru/catalog/tsementno-peschanye-smesi/sukhaya_smes_m_200_montazhno_kladochnaya/ | O30: В характеристиках фасовки нет; «на 1 мешок 50 кг» взято из раздела работ. Фразы «для наружных/внутренних работ» нет. Стяжка по разделу работ — слоем 30-80 мм. Зимние модификации -5/-10/-15°С (значение «от * °С»). Расход 20 кг/м² указан на слой 10 мм.
A31: Dauer | B31: Цементно-песчаные смеси М150–М400, пескобетон | C31: да | D31: Dauer М-300 Пескобетон | E31: Dauer® Сухая смесь М-300 Пескобетон | F31: 1 | G31: Сухая смесь пескобетон предназначена для выполнения общестроительных работ: устройство высокопрочных стяжек ("мокрого" типа); заделка швов, трещин, выбоин, углублений; крепление металлических элементов и монтаж железобетонных конструкций; возведение стен и конструкций из полнотелого рядового кирпича, полнотелых бетонных блоков и природного камня. | H31: 30 кг, 40 кг, 50 кг | I31: 20 кг/м² | J31: Толщина слоя нанесения составляет 30-200 мм | K31: ГОСТ 28013-98 | L31: есть | N31: https://dauer.ru/catalog/tsementno-peschanye-smesi/sukhaya_smes_m_300_peskobeton/ | O31: Пескобетон М300. Можно отнести и к floor_screed (основное применение — стяжки), но по классификатору оставлен в ЦПС. С щебнем 5–20 мм в соотношении 1:2 даёт бетонную смесь. Фразы «для наружных/внутренних работ» нет. Зимние модификации -10/-15°С. Расход 20 кг/м² указан на слой 10 мм.
A32: Dauer | B32: Цементно-песчаные смеси М150–М400, пескобетон | C32: да | D32: Dauer М-400 Пескобетон высокопрочный | E32: Dauer® Сухая смесь М-400 Пескобетон высокопрочный | F32: 1 | G32: Сухая смесь пескобетон предназначена для выполнения общестроительных работ: устройство высокопрочных стяжек ("мокрого" типа); заделка швов, трещин, выбоин, углублений; крепление металлических элементов и монтаж железобетонных конструкций; возведение стен и конструкций из полнотелого рядового кирпича, полнотелых бетонных блоков и природного камня. | H32: 40 кг | I32: 20 кг/м² | J32: слоем 30-70 мм | K32: ГОСТ 28013-98 | L32: есть | N32: https://dauer.ru/catalog/tsementno-peschanye-smesi/sukhaya-smes-m-400-peskobeton-vysokoprochnyy/ | O32: Описание назначения слово в слово совпадает с М-300; отличия — марка М400 и фасовка (только 40 кг). В разделе работ: стяжка слоем 30-70 мм, отмостка, мощение, заполнение швов. Фразы «для наружных/внутренних работ» нет. Расход 20 кг/м² указан на слой 10 мм.
A33: Perel | B33: Цементно-песчаные смеси М150–М400, пескобетон | C33: да | D33: Perel М-150 Базовый | E33: М-150 Базовый, 50 кг | F33: 1 | G33: Цементно-песчаная смесь с пластифицирующими добавками. Рекомендуется для выполнения кладочных работ рядовым кирпичом. | H33: Бумажные крафт-мешки по 50 кг. | L33: есть | N33: https://td-perel.ru/catalog/universalnye-smesi/m-150-bazovyy/ | O33: Марка М150 — только в названии; характеристик (прочность, расход) нет, артикул «-». Упомянута модификация «зима» без отдельного артикула. Бренд Perel в названии не стоит (упомянута грунтовка «PEREL»). В инструкции фраза про «поверхности пола» — похоже, текст скопирован с другой карточки. Нанесение по СП 70.13330.2012.
A34: Perel | B34: Цементно-песчаные смеси М150–М400, пескобетон | C34: да | D34: Perel М-150 Универсальный | E34: М-150 Универсальный, 40 кг | F34: 1 | G34: Применяется для штукатурно-кладочных работ. | H34: Бумажные крафт-мешки по 40 кг. | K34: СП 70.13330.2012 | L34: есть | N34: https://td-perel.ru/catalog/universalnye-smesi/m-150-universalnyy/ | O34: Блок «Характеристики» на странице пуст (только Артикул «-»); пары кроме артикула взяты из описания. Расход и толщина слоя не указаны. Зимняя версия упомянута в тексте («с модификацией «зима»»), отдельной карточки в пачке нет. СП 70.13330.2012 — свод правил на производство работ, а не стандарт на смесь. Описание шире краткого: «Применяется для выравнивания поверхностей по минеральным основаниям (бе
A35: Perel | B35: Цементно-песчаные смеси М150–М400, пескобетон | C35: да | D35: Perel М-300 Пескобетон | E35: М-300, 50 кг | F35: 1 | G35: Сухая строительная смесь Пескобетон М 300 применяется как мелкозернистый бетон для заливки фундаментов, изготовления высокопрочных бетонных стяжек различной толщины, в качестве несущего слоя полов, при обустройстве жилых, общественных и производственных помещений, гаражей, зон повышенного потока людей, при монтажно-кладочных работах, для возведения и ремонта бетонных стен и оснований. | H35: Бумажные крафт-мешки по 50 кг. | J35: Минимальная толщина слоя 25мм. | L35: есть | N35: https://td-perel.ru/catalog/universalnye-smesi/m-300/ | O35: Пескобетон; лежит в разделе «Универсальные смеси», по тексту в основном стяжка и фундамент (подошёл бы и floor_screed), выбран masonry_universal_cps как пескобетон. Название на странице «М-300, 50 кг», в тексте «Пескобетон М300» и «Пескобетон М 300» (разное написание). Блок «Характеристики» пуст (Артикул «-»), пары взяты из описания. Расход не указан. Основа явно не названа. Зимняя модификация упо
A36: Dauer | B36: Штукатурки гипсовые | C36: да | D36: Dauer SLIDER 36 | E36: Dauer SLIDER® 36 Штукатурка гипсовая универсальная серая | F36: 2 | G36: Для машинного и ручного выравнивания стен: сплошного (от 5 до 50 мм) и частичного при локальном выравнивании (до 60 мм), выравнивания потолков (до 10 мм) – внутри помещений с умеренной влажностью под последующую отделку (финишное тонкослойное шпатлевание, оклейку обоями, многослойное окрашивание). | H36: 30 кг. | I36: 9 – 10 кг/м² | J36: сплошного (от 5 до 50 мм) | K36: ГОСТ Р 58279 | L36: — | N36: https://dauer.ru/catalog/shtukaturki/slider-36/ | O36: Серая; белая версия — SLIDER 36W, у неё тот же series_key. Расход 9–10 кг/м² указан на слой 10 мм. Декларация РОСС RU (кода товара в имени файла нет) не включена. Полное наименование «Dauer Slider Интерьер (Interier) 36».
A37: Dauer | B37: Штукатурки гипсовые | C37: да | D37: Dauer SLIDER 37 | E37: Dauer SLIDER® 37 Штукатурка гипсовая теплая армированная | F37: 2 | G37: Для машинного и ручного выравнивания стен: сплошного (от 3 до 50 мм) и частичного, при локальном выравнивании (до 80 мм), для выравнивания потолков (до 30 мм), внутри помещений с умеренной влажностью под последующую отделку (финишное тонкослойное шпатлевание, оклейку обоями, многослойное окрашивание). | H37: 30 кг. | I37: 0,8 кг/м² | J37: сплошного (от 3 до 50 мм) | K37: ГОСТ Р 58279-2024 | L37: — | N37: https://dauer.ru/catalog/shtukaturki/slider-37/ | O37: «Тёплая армированная» гипсовая штукатурка, не кладочный раствор. Техкарта подписана «…с перлитом». В особенностях опечатка сайта «Идеальное качество без шатлевания». Расход 0,8 кг/м² указан на слой 1 мм. Белая версия — 37W, у неё тот же series_key. Полное наименование «Dauer Slider Интерьер (Interier) 37».
A38: Dauer | B38: Штукатурки гипсовые | C38: да | D38: Dauer SLIDER 38 | E38: Dauer SLIDER® 38 Штукатурка гипсовая легкая с перлитом | F38: 2 | G38: Для машинного и ручного выравнивания стен: сплошного (от 3 до 50 мм) и частичного, при локальном выравнивании (до 80 мм), для выравнивания потолков (до 30 мм), внутри помещений с умеренной влажностью под последующую отделку (шпатлевание, оклейку обоями, многослойное окрашивание). | H38: 30 кг. | I38: 0,8 кг/м² | J38: сплошного (от 3 до 50 мм) | K38: ГОСТ Р 58279-2024 | L38: — | N38: https://dauer.ru/catalog/shtukaturki/slider-38/ | O38: Расхождение: в описании сплошной слой от 3 до 50 мм, в характеристиках «Толщина слоя при сплошном нанесении 5-50 мм». Расход 0,8 кг/м² указан на слой 1 мм. Белая версия — 38W, у неё тот же series_key. Полное наименование «Dauer Slider Интерьер (Interier) 38».
A39: Dauer | B39: Штукатурки гипсовые | C39: да | D39: Dauer SLIDER 39 | E39: Dauer SLIDER® 39 Штукатурка гипсовая универсальная влагостойкая | F39: 1 | G39: Для машинного и ручного выравнивания стен: сплошного (от 5 до 50 мм) и частичного при локальном выравнивании (до 80 мм), для выравнивания потолков (до 20 мм), внутри помещений с нормальной и повышенной влажностью под последующую отделку: финишное тонкослойное шпатлевание, оклейку обоями, многослойное окрашивание, облицовку керамической плиткой малого формата (размер грани не более 30 см) с тщательной затиркой межплиточных швов. | H39: 30 кг. | I39: 10 – 11 кг/м² | J39: сплошного (от 5 до 50 мм) | K39: ГОСТ Р 58279 | L39: — | N39: https://dauer.ru/catalog/shtukaturki/slider-39/ | O39: Влагостойкая гипсовая. Расхождение по воде: в характеристиках 0,30–0,35 л на 1 кг, в разделе «Выполнение работ» 0,25–0,28 л (7,5–8,5 л на мешок 30 кг). Ссылка в документах подписана «DAUER SLIDER 312 Штукатурка цементная мелкофракционная гладкая» — похоже на ошибку сайта. Есть «Рекомендательное письмо SLIDER INTERIER 39». Расход 10–11 кг/м² указан на слой 10 мм.
A40: Perel | B40: Штукатурки гипсовые | C40: да | D40: Perel Plast | E40: Perel Plast, 30 кг, белая, пластичная гипсовая штукатурка с увеличенным временем жизни | F40: 1 | G40: Пластичная гипсовая штукатурная смесь на основе природного гипса, минерального наполнителя и полимерных добавок, для выравнивания стен (до 50 мм) из бетона, газобетона, кирпича и каменных поверхностей ручным способом, внутри жилых и общественных сухих помещений с нормальным уровнем температуры и влажности. | H40: Бумажные крафт-мешки по 30 кг. | J40: Рекомендуемый слой нанесения составляет 5-50мм за один проход. | L40: — | N40: https://td-perel.ru/catalog/gipsovaya-shtukaturka/gipsovaya-shtukaturka-plastichnaya-perel-plast-belaya-30-kg/ | O40: Расхождение: лид «Для ручного или машинного нанесения», описание — «ручным способом». Расход не указан. Срок хранения 6 месяцев. Есть раздел «Видеообзоры» (в полном тексте только заголовок). В «Характеристиках» только артикул.
...

Sheet Карточки
A1: Производитель | B1: Тип страницы | C1: Название (h1) | D1: Товар | E1: Вариант | F1: Наш тип | G1: Сухая | H1: Назначение — дословно | I1: Фасовка — дословно | J1: Расход — дословно | K1: Метки | L1: Ссылка
A2: Dauer | B2: product | C2: Dauer BRICK.COLOR 250 цветная кладочная смесь армированная | D2: Dauer BRICK.COLOR 250 | F2: masonry_colored | G2: yes | H2: Для монтажа и одновременной отделки швов кладочных элементов с водопоглощением от 6 до 12% | I2: 3,5 – 4,5 литра воды на мешок 25 кг или 7 – 9 литров на мешок 50 кг | K2: Новинка | L2: https://dauer.ru/catalog/montazhnye-i-kladochnye/dauer-brick-color-250/
A3: Dauer | B3: product | C3: Dauer BRICK.COLOR 251 цветная кладочная смесь армированная | D3: Dauer BRICK.COLOR 251 | F3: masonry_colored | G3: yes | H3: Для монтажа и одновременной отделки швов кладочных элементов с водопоглощением от 5 до 18% (полнотелый и пустотелый облицовочный керамический кирпич, кирпич ручной формовки, рядовой керамический и плотный силикатный кирпич, кирпичи или блоки из бетона и натурального камня). | I3: 3,5 – 4,5 литра воды на мешок 25 кг или 7 – 9 литров на мешок 50 кг | K3: Новинка | L3: https://dauer.ru/catalog/montazhnye-i-kladochnye/dauer-brick-color-251/
A4: Dauer | B4: product | C4: Dauer BRICK.COLOR 252 цветная кладочная смесь армированная | D4: Dauer BRICK.COLOR 252 | F4: masonry_colored | G4: yes | H4: Для монтажа и одновременной отделки швов кладочных элементов с водопоглощением от 1 до 5% (полнотелый и пустотелый облицовочный клинкерный кирпич, блоки из бетона и натурального камня). | I4: Смесь поставляется в бумажных мешках. | K4: Новинка | L4: https://dauer.ru/catalog/montazhnye-i-kladochnye/dauer-brick-color-252/
A5: Dauer | B5: product | C5: Dauer BRICK.COLOR 253 кладочная смесь для рядового кирпича | D5: Dauer BRICK.COLOR 253 | F5: masonry_ordinary | G5: yes | H5: Предназначена для монтажа забутовочных кладочных элементов (полнотелый и пустотелый керамический кирпич, натуральный камень, рядовой керамический и плотный силикатный кирпич, кирпичи из бетона). | I5: 3,25 – 3,75 литра воды на мешок 25 кг или 6,5 – 7,5 литров на мешок 50 кг | K5: Новинка | L5: https://dauer.ru/catalog/montazhnye-i-kladochnye/dauer-brick-color-253/
A6: Dauer | B6: product | C6: Dauer CONECTOR® 02 Клей Оптимум C0 Т | D6: Dauer CONECTOR 02 | F6: tile_adhesive | G6: yes | H6: Для укладки на пол и стены керамической плитки по ГОСТ 13996 (со средним и высоким водопоглощением) и других облицовочных материалов с водопоглощением не менее 5%. Применяется внутри помещений с любым уровнем влажности. | I6: 25 кг. | J6: 1,3 – 1,4 кг/м² | L6: https://dauer.ru/catalog/plitochnye-klei/conector-02/
A7: Dauer | B7: product | C7: Dauer CONECTOR® 14 Клей Армированный С1 TЕ | D7: Dauer CONECTOR 14 | F7: tile_adhesive | G7: yes | H7: Для выполнения работ по облицовке фасадов выше цокольной части и помещений с любым уровнем влажности. Применяется для укладки керамической плитки, керамогранита и натурального камня весом до 150 кг/м2. | I7: 25 кг. | J7: 1,3 – 1,4 кг/м² | L7: https://dauer.ru/catalog/plitochnye-klei/conector-14/
A8: Dauer | B8: product | C8: Dauer CONECTOR® 22 Клей высокоэффективный С2 T | D8: Dauer CONECTOR 22 | F8: tile_adhesive | G8: yes | H8: Для наружных и внутренних облицовочных работ фасадов зданий и сооружений (включая цокольную часть) крупноформатными облицовочными материалами (керамическая и клинкерная плитка, натуральный камень и керамогранит). | I8: 25 кг. | J8: 1,3 – 1,4 кг/м² | L8: https://dauer.ru/catalog/plitochnye-klei/conector-force-22-kley-vysokoeffektivnyy-s2-t-gost-r-56387/
A9: Dauer | B9: product | C9: Dauer CONECTOR® 22 Макс Клей Армированный С2 TЕ | D9: Dauer CONECTOR 22 Макс | F9: tile_adhesive | G9: yes | H9: Для наружных и внутренних облицовочных работ фасадов зданий и сооружений (включая цокольную часть) крупноформатными облицовочными материалами (керамическая и клинкерная плитка, натуральный камень и керамогранит). | I9: 25 кг. | J9: 1,3 – 1,4 кг/м² | L9: https://dauer.ru/catalog/plitochnye-klei/conector-22-max/
A10: Dauer | B10: product | C10: Dauer CONECTOR® Плюс Клей Универсальный C1 T | D10: Dauer CONECTOR Плюс | F10: tile_adhesive | G10: yes | H10: Для укладки на пол и стены керамической и клинкерной плитки, керамогранита и натурального камня (кроме мрамора, базальта, габбро) весом до 80 кг/м². | I10: 25/40 кг. | J10: 1,3 – 1,4 кг/м² | K10: Хит | L10: https://dauer.ru/catalog/plitochnye-klei/conector-home-plus-kley-universalnyy-c1-gost-r-56387-2018/
A11: Dauer | B11: product | C11: Dauer FINNER® 40W Шпатлевка цементная армированная базовая белая | D11: Dauer FINNER 40 | E11: белая (W) | F11: putty_cement | G11: yes | H11: Для толстослойного и финишного выравнивания (слой от 1 до 15 мм) поверхности фасадов, стен и потолков внутри всех видов жилых и нежилых помещений, в т.ч. влажных и неотапливаемых: подвалы, балконы и лоджии, паркинги, лестничные пролеты, марши, склады, душевые и ванные комнаты. | I11: 25 кг. | J11: 0,9 кг/м2 | L11: https://dauer.ru/catalog/shpatlevki/finner-exter-40w-shpatlevka-tsementnaya-armirovannaya-bazovaya-belaya/
A12: Dauer | B12: product | C12: Dauer FINNER® 40G Шпатлевка цементная армированная базовая серая | D12: Dauer FINNER 40 | E12: серая (G) | F12: putty_cement | G12: yes | H12: Для толстослойного и финишного выравнивания (слой от 1 до 15 мм) поверхности фасадов, стен и потолков внутри всех видов помещений, в т.ч. влажных и неотапливаемых. | I12: 25 кг. | J12: 0,9 кг/м2 | L12: https://dauer.ru/catalog/shpatlevki/finner-40g/
A13: Dauer | B13: product | C13: Dauer FINNER® 41W Шпатлевка цементная финишная белая 180/6,5/F50 ГОСТ 33699 | D13: Dauer FINNER 41 | E13: белая (W) | F13: putty_cement | G13: yes | H13: Для финишного выравнивания (слой от 0,2 до 5 мм) поверхности фасадов, стен и потолков, внутри всех видов помещений, в т.ч. влажных и неотапливаемых: подвалы, лоджии, балконы, паркинги, лестничные пролеты, марши, склады, душевые и ванные комнаты. | I13: 20 кг. | J13: 1 кг/м2 | L13: https://dauer.ru/catalog/shpatlevki/finner-exter-41w-shpatlevka-tsementnaya-finishnaya-belaya/
A14: Dauer | B14: product | C14: Dauer FINNER® 41G Шпатлевка цементная финишная серая | D14: Dauer FINNER 41 | E14: серая (G) | F14: putty_cement | G14: yes | H14: Для финишного выравнивания (слой от 0,2 до 5 мм) поверхности фасадов, стен и потолков, внутри всех видов помещений, в т.ч. влажных и неотапливаемых: подвалы, лоджии, балконы, паркинги, лестничные пролеты, марши, склады, душевые и ванные комнаты. Используется для выравнивания поверхности под нанесение финишных декоративных покрытий и многослойное окрашивание ЛКМ. | I14: 20 кг. | J14: 0,9 кг/м2 | L14: https://dauer.ru/catalog/shpatlevki/finner-exter-41g-shpatlevka-tsementnaya-finishnaya-seraya/
A15: Dauer | B15: product | C15: Dauer FINNER® 43W Шпатлевка гипсовая универсальная белая | D15: Dauer FINNER 43 | E15: белая (W) | F15: putty_gypsum | G15: yes | H15: Внутри сухих отапливаемых помещений для толстослойного и финишного выравнивания (слой от 1 до 20 мм) поверхности стен и потолков под дальнейшую отделку обоями и нанесения финишных декоративных покрытий; для заделки трещин, выбоин, раковин слоем до 20 мм, для заполнения швов ГВЛ, ГКЛ с обязательным применением армирующей ленты. | I15: 20 кг. | J15: 0,9 кг/м² | L15: https://dauer.ru/catalog/shpatlevki/finner-43/
A16: Dauer | B16: product | C16: Dauer IMMER® 60 Грунт глубокого проникновения | D16: Dauer IMMER 60 | F16: primer | G16: no | H16: Для обработки и обеспыливания минеральных оснований, под последующее нанесение отделочных материалов: цементных и гипсовых штукатурок, цементных, гипсовых и полимерных шпаклёвок, плиточных и монтажных клеёв, лакокрасочных материалов, обоев и других финишных декоративных покрытий. | I16: e 10 л / НЕТТО 10 кг | J16: 100-120 мл/м² | K16: Новинка, Новая, улучшенная рецептура | L16: https://dauer.ru/catalog/grunty/immer-made-60-grunt-bazovyy-ukreplyayushchiy-na-akrilovoy-osnove/
A17: Dauer | B17: product | C17: Dauer IMMER® 65 Про Грунт глубокого проникновения | D17: Dauer IMMER 65 | F17: primer | G17: no | H17: Для предварительной обработки и обеспыливания минеральных оснований. Рекомендуется для упрочнения старых, рыхлых, непрочных и сильновпитывающих оснований. | I17: 5 л./10 л. | J17: 100-120 мл/м² | K17: Новинка, Новая, улучшенная рецептура | L17: https://dauer.ru/catalog/grunty/immer-made-65-grunt-glubokogo-proniknoveniya/
A18: Dauer | B18: product | C18: Dauer PLATTER® 50 Стяжка высокопрочная армированная | D18: Dauer PLATTER 50 | F18: floor_screed | G18: yes | H18: Применяется для базового толстослойного выравнивания полов, для устройства контактных стяжек и стяжек на разделительном слое, в том числе "плавающих". | I18: 25 кг. | J18: 18 кг/м² | K18: Новинка | L18: https://dauer.ru/catalog/materialy-dlya-ustroystva-polov/dauer-platter-50/
A19: Dauer | B19: product | C19: Dauer PLATTER® 55 Наливной пол универсальный быстротвердеющий | D19: Dauer PLATTER 55 | F19: floor_self_leveling | G19: yes | H19: Для ручного и механизированного выравнивания оснований (от 2 до 100 мм) под последующую укладку напольных покрытий: ламинат, линолеум и ковролин, керамическая и керамогранитная плитка, другие выстилающие покрытия. | I19: 20 кг. | J19: 1,4-1,6 кг/м² | L19: https://dauer.ru/catalog/materialy-dlya-ustroystva-polov/platter-self-55-eco-nalivnoy-pol-universalnyy-bystrotverdeyushchiy-rk5-vtb4-v12-5-gost-31358-2019/
A20: Dauer | B20: product | C20: Dauer PLATTER® 57 Наливной пол армированный быстротвердеющий | D20: Dauer PLATTER 57 | F20: floor_self_leveling | G20: yes | H20: Для ручного и механизированного выравнивания оснований (от 1 до 15 мм) под последующую укладку напольных покрытий. | I20: 20 кг. | J20: 1,5-1,6 кг/м² | L20: https://dauer.ru/catalog/materialy-dlya-ustroystva-polov/platter-self-57-nalivnoy-pol-tonkosloynyy-bystrotverdeyushchiy-klass-v15-gost-31358/
A21: Dauer | B21: product | C21: Dauer PLATTER® 59 Наливной пол армированный высокопрочный | D21: Dauer PLATTER 59 | F21: floor_self_leveling | G21: yes | H21: Для ручного и механизированного выравнивания оснований от 2 до 30 мм, с возможностью локального выравнивания до 50 мм, эксплуатируемых в жилых, офисных, торговых или иных общественных помещениях с умеренной и повышенной влажностью, в условиях умеренных и значительных нагрузок, под последующую укладку напольных покрытий, а также под проведение облицовочных работ плитами из керамогранита или натурального камня. | I21: 25 кг. | J21: 1,7 кг/м2 | L21: https://dauer.ru/catalog/materialy-dlya-ustroystva-polov/platter-self-59-nalivnoy-pol-vysokoprochnyy-rk6-vtb4-v20-f50-gost-31358/
A22: Dauer | B22: product | C22: Dauer QUADER D600 клей для блоков усиленный | D22: Dauer QUADER D600 | F22: block_adhesive | G22: yes | H22: Для возведения стен и перегородок из блоков на основе газо- и пенобетона, силикатного пенобетона, полистиролбетона и других ячеистых блоков. | I22: 25 кг, 40 кг | J22: Расход раствора при слое шва 2 мм | K22: Хит | L22: https://dauer.ru/catalog/montazhnye-i-kladochnye/block-d600-kley-montazhnyy/
A23: Dauer | B23: product | C23: Dauer SAVER 707 Гидроизоляция готовая полимерная | D23: Dauer SAVER 707 | F23: waterproofing_liquid | G23: no | H23: Гидроизоляция готовая на полимерной основе, предназначена для создания эластичного гидроизоляционного покрытия на горизонтальных и вертикальных поверхностях в помещениях под последующую укладку керамической и клинкерной плитки, керамогранита, натурального и искусственного камня, подверженных периодическому увлажнению (ванных, душевых, туалетах, кухнях и т.д.). | I23: 14 кг. | J23: 1,4 кг/м2 | L23: https://dauer.ru/catalog/gidroizolyatsiya/dauer-saver-707/
A24: Dauer | B24: product | C24: Dauer SLIDER® 301 Штукатурка цементно-известковая выравнивающая облегченная | D24: Dauer SLIDER 301 | F24: plaster_cement | G24: yes | H24: Штукатурка цементно-известковая выравнивающая облегченная SLIDER® 301 предназначена для ручного и механизированного высококачественного выравнивания (слой 5 – 40 мм) поверхности фасадов зданий и сооружений, стен внутри всех видов помещений в т.ч. влажных и неотапливаемых: подвалы, балконы и лоджии, паркинги, лестничные пролеты, марши, склады, другие помещения с переменной влажностью. | I24: 40 кг. | J24: 12,5 кг/м2 | K24: Новинка | L24: https://dauer.ru/catalog/shtukaturki/slider-fasad-301/
A25: Dauer | B25: product | C25: Dauer SLIDER® 302 Штукатурка цементно-известковая гладкая | D25: Dauer SLIDER 302 | F25: plaster_cement | G25: yes | H25: Штукатурка цементно-известковая гладкая Dauer SLIDER® 302 предназначена для ручного и механизированного высококачественного выравнивания (слой 5 – 40 мм) поверхности фасадов зданий и сооружений, стен внутри всех видов помещений в т.ч. влажных и неотапливаемых: подвалы, балконы и лоджии, паркинги, лестничные пролеты, марши, склады, другие помещения с переменной влажностью. | I25: 25 кг. | J25: 12,5 кг/м2 | K25: Новинка | L25: https://dauer.ru/catalog/shtukaturki/slider-fasad-302/
A26: Dauer | B26: product | C26: Dauer SLIDER® 31 Штукатурка цементная мелкофракционная гладкая | D26: Dauer SLIDER 31 Slim | F26: plaster_cement | G26: yes | H26: Для ручного и механизированного выравнивания слоем от 3 мм. (локально) до 30 мм. поверхности фасадов, стен внутри всех видов помещений, в т.ч. влажных и неотапливаемых: подвалы, лоджии, паркинги, лестничные пролеты, марши, склады, душевые и ванные комнаты. | I26: 25 кг, 40 кг | J26: 12 - 13 кг/м² | K26: Хит | L26: https://dauer.ru/catalog/shtukaturki/slider-fasad-31-slim-shtukaturka-tsementnaya-melkofraktsionnaya-gladkaya-kp-iii-gost-33083-2014/
A27: Dauer | B27: product | C27: Dauer SLIDER® 31 Фибра Штукатурка цементная выравнивающая армированная | D27: Dauer SLIDER 31 Фибра | F27: plaster_cement | G27: yes | H27: Для ручного и механизированного выравнивания (слоем 5 - 40 мм) поверхности фасадов, стен внутри всех видов помещений, в т.ч. влажных и неотапливаемых: подвалы, балконы и лоджии, паркинги, лестничные пролеты, марши, склады, душевые и ванные комнаты. Для ремонта сколов, выбоин, раковин, трещин глубиной до 50 мм. | I27: 25 кг, 40 кг | J27: 14 - 15 кг/м² | K27: Хит | L27: https://dauer.ru/catalog/shtukaturki/slider-fasad-31-fibro-shtukaturka-tsementnaya-vyravnivayushchaya-armirovannaya-kp-iii-gost-33083-201/
A28: Dauer | B28: product | C28: Dauer SLIDER® 312 Штукатурка цементная гладкая с перлитом | D28: Dauer SLIDER 312 | F28: plaster_cement | G28: yes | H28: Для высококачественного выравнивания (слой 3 – 40 мм) поверхности фасадов зданий и сооружений, стен внутри всех видов помещений в т.ч. влажных и неотапливаемых: подвалы, балконы и лоджии, паркинги, лестничные пролеты, марши, склады, душевые и ванные комнаты. | I28: 30 кг. | J28: 12 кг/м2 | L28: https://dauer.ru/catalog/shtukaturki/slider-312/
A29: Dauer | B29: product | C29: Dauer SLIDER® 321 штукатурка цементная высокопрочная фасадная | D29: Dauer SLIDER 321 | F29: plaster_cement | G29: yes | H29: Штукатурка цементная высокопрочная фасадная SLIDER® 321 предназначена для ручного и механизированного высококачественного выравнивания (слой 10 – 40 мм, локально от 5 мм.) поверхности фасадов и цоколей зданий и сооружений, стен снаружи и внутри всех видов помещений в т.ч. влажных и неотапливаемых: подвалы, балконы и лоджии, паркинги, лестничные пролеты, марши, склады, другие помещения с переменной влажностью. | I29: 40 кг. | J29: 16 кг/м2 | K29: Новинка | L29: https://dauer.ru/catalog/shtukaturki/dauer-slider-321/
A30: Dauer | B30: product | C30: Dauer SLIDER® 36W Штукатурка гипсовая универсальная белая | D30: Dauer SLIDER 36 | E30: белая (W) | F30: plaster_gypsum | G30: yes | H30: Для машинного и ручного выравнивания стен: сплошного (от 5 до 50 мм) и частичного при локальном выравнивании (до 60 мм), выравнивания потолков (до 10 мм) – внутри помещений с умеренной влажностью под последующую отделку (оклейку обоями, многослойное окрашивание, шпатлевание). | I30: 30 кг. | J30: 0,9 – 1,0 кг/м² | K30: Хит | L30: https://dauer.ru/catalog/shtukaturki/slider-interier-36w-shtukaturka-gipsovaya-universalnaya-belaya-90-2-0-gost-r-58279-2018/
A31: Dauer | B31: product | C31: Dauer SLIDER® 36 Штукатурка гипсовая универсальная серая | D31: Dauer SLIDER 36 | E31: серая | F31: plaster_gypsum | G31: yes | H31: Для машинного и ручного выравнивания стен: сплошного (от 5 до 50 мм) и частичного при локальном выравнивании (до 60 мм), выравнивания потолков (до 10 мм) – внутри помещений с умеренной влажностью под последующую отделку (финишное тонкослойное шпатлевание, оклейку обоями, многослойное окрашивание). | I31: 30 кг. | J31: 9 – 10 кг/м² | L31: https://dauer.ru/catalog/shtukaturki/slider-36/
A32: Dauer | B32: product | C32: Dauer SLIDER® 37W Штукатурка гипсовая тёплая армированная белая | D32: Dauer SLIDER 37 | E32: белая (W) | F32: plaster_gypsum | G32: yes | H32: Для машинного и ручного выравнивания стен: сплошного (от 3 до 50 мм) и частичного, при локальном выравнивании (до 80 мм), для выравнивания потолков (до 30 мм), внутри помещений с умеренной влажностью под последующую отделку (финишное тонкослойное шпатлевание, оклейку обоями, многослойное окрашивание). | I32: 30 кг. | J32: 0,8 кг/м² | L32: https://dauer.ru/catalog/shtukaturki/slider-37w/
A33: Dauer | B33: product | C33: Dauer SLIDER® 37 Штукатурка гипсовая теплая армированная | D33: Dauer SLIDER 37 | E33: серая | F33: plaster_gypsum | G33: yes | H33: Для машинного и ручного выравнивания стен: сплошного (от 3 до 50 мм) и частичного, при локальном выравнивании (до 80 мм), для выравнивания потолков (до 30 мм), внутри помещений с умеренной влажностью под последующую отделку (финишное тонкослойное шпатлевание, оклейку обоями, многослойное окрашивание). | I33: 30 кг. | J33: 0,8 кг/м² | L33: https://dauer.ru/catalog/shtukaturki/slider-37/
